<?xml version="1.0" ?>
<robot name="Xarm6" xmlns:xacro="http://www.ros.org/wiki/xacro">

<xacro:include filename="materials.xacro" />
<xacro:include filename="Xarm6.trans" />
<xacro:include filename="Xarm6.gazebo" />
<link name="base_link">
  <inertial>
    <origin xyz="-0.0014966838440202384 9.275029853168595e-05 0.07347393172350347" rpy="0 0 0"/>
    <mass value="9.182566175577422"/>
    <inertia ixx="0.024904" iyy="0.025698" izz="0.011792" ixy="5.9e-05" iyz="3.8e-05" ixz="-0.000637"/>
  </inertial>
  <visual>
    <origin xyz="0 0 0" rpy="0 0 0"/>
    <geometry>
      <mesh filename="package://Xarm6_description/meshes/base_link.stl" scale="0.001 0.001 0.001"/>
    </geometry>
    <material name="silver"/>
  </visual>
  <collision>
    <origin xyz="0 0 0" rpy="0 0 0"/>
    <geometry>
      <mesh filename="package://Xarm6_description/meshes/base_link.stl" scale="0.001 0.001 0.001"/>
    </geometry>
  </collision>
</link>

<link name="link1_1_1_1">
  <inertial>
    <origin xyz="0.0002132169716367933 0.007397272830046666 0.0850878241893451" rpy="0 0 0"/>
    <mass value="10.406228242971363"/>
    <inertia ixx="0.030675" iyy="0.025411" izz="0.017209" ixy="-2.3e-05" iyz="-0.003241" ixz="-5.9e-05"/>
  </inertial>
  <visual>
    <origin xyz="-3e-06 -5e-06 -0.1548" rpy="0 0 0"/>
    <geometry>
      <mesh filename="package://Xarm6_description/meshes/link1_1_1_1.stl" scale="0.001 0.001 0.001"/>
    </geometry>
    <material name="silver"/>
  </visual>
  <collision>
    <origin xyz="-3e-06 -5e-06 -0.1548" rpy="0 0 0"/>
    <geometry>
      <mesh filename="package://Xarm6_description/meshes/link1_1_1_1.stl" scale="0.001 0.001 0.001"/>
    </geometry>
  </collision>
</link>

<link name="link2_1_1_1">
  <inertial>
    <origin xyz="0.013535388574605242 -0.04870515037578728 0.16519026278797577" rpy="0 0 0"/>
    <mass value="21.143001773162247"/>
    <inertia ixx="0.240188" iyy="0.213104" izz="0.068928" ixy="0.006223" iyz="0.059808" ixz="-0.034226"/>
  </inertial>
  <visual>
    <origin xyz="-0.000349 -0.075304 -0.266798" rpy="0 0 0"/>
    <geometry>
      <mesh filename="package://Xarm6_description/meshes/link2_1_1_1.stl" scale="0.001 0.001 0.001"/>
    </geometry>
    <material name="silver"/>
  </visual>
  <collision>
    <origin xyz="-0.000349 -0.075304 -0.266798" rpy="0 0 0"/>
    <geometry>
      <mesh filename="package://Xarm6_description/meshes/link2_1_1_1.stl" scale="0.001 0.001 0.001"/>
    </geometry>
  </collision>
</link>

<link name="link3_1_1_1">
  <inertial>
    <origin xyz="0.06336946362255372 -0.02985893230455631 -0.08140784089768266" rpy="0 0 0"/>
    <mass value="10.22532102231252"/>
    <inertia ixx="0.041465" iyy="0.035247" izz="0.030495" ixy="0.00708" iyz="-0.01272" ixz="0.010135"/>
  </inertial>
  <visual>
    <origin xyz="-0.053671 -0.067014 -0.55147" rpy="0 0 0"/>
    <geometry>
      <mesh filename="package://Xarm6_description/meshes/link3_1_1_1.stl" scale="0.001 0.001 0.001"/>
    </geometry>
    <material name="silver"/>
  </visual>
  <collision>
    <origin xyz="-0.053671 -0.067014 -0.55147" rpy="0 0 0"/>
    <geometry>
      <mesh filename="package://Xarm6_description/meshes/link3_1_1_1.stl" scale="0.001 0.001 0.001"/>
    </geometry>
  </collision>
</link>

<link name="link4_1_1_1">
  <inertial>
    <origin xyz="-0.0001590814276628827 -0.03244192062082851 -0.10206068450371575" rpy="0 0 0"/>
    <mass value="6.198939907886892"/>
    <inertia ixx="0.034346" iyy="0.030946" izz="0.00815" ixy="-2.8e-05" iyz="-0.007003" ixz="-1.6e-05"/>
  </inertial>
  <visual>
    <origin xyz="-0.131425 0.000482 -0.382365" rpy="0 0 0"/>
    <geometry>
      <mesh filename="package://Xarm6_description/meshes/link4_1_1_1.stl" scale="0.001 0.001 0.001"/>
    </geometry>
    <material name="silver"/>
  </visual>
  <collision>
    <origin xyz="-0.131425 0.000482 -0.382365" rpy="0 0 0"/>
    <geometry>
      <mesh filename="package://Xarm6_description/meshes/link4_1_1_1.stl" scale="0.001 0.001 0.001"/>
    </geometry>
  </collision>
</link>

<link name="link5_1_1_1">
  <inertial>
    <origin xyz="0.04893547801546441 0.013357760681958413 -0.01112659191452961" rpy="0 0 0"/>
    <mass value="5.676003654765444"/>
    <inertia ixx="0.006607" iyy="0.013098" izz="0.011418" ixy="0.00217" iyz="-0.000571" ixz="0.001709"/>
  </inertial>
  <visual>
    <origin xyz="-0.131434 0.005248 -0.209369" rpy="0 0 0"/>
    <geometry>
      <mesh filename="package://Xarm6_description/meshes/link5_1_1_1.stl" scale="0.001 0.001 0.001"/>
    </geometry>
    <material name="silver"/>
  </visual>
  <collision>
    <origin xyz="-0.131434 0.005248 -0.209369" rpy="0 0 0"/>
    <geometry>
      <mesh filename="package://Xarm6_description/meshes/link5_1_1_1.stl" scale="0.001 0.001 0.001"/>
    </geometry>
  </collision>
</link>

<link name="end_effector_1_1_1">
  <inertial>
    <origin xyz="0.017458665945886548 0.0026089112471743992 -0.015178589483564653" rpy="0 0 0"/>
    <mass value="1.0716475117579791"/>
    <inertia ixx="0.000482" iyy="0.004111" izz="0.004417" ixy="-0.000182" iyz="1.6e-05" ixz="0.000259"/>
  </inertial>
  <visual>
    <origin xyz="-0.207437 0.000906 -0.140853" rpy="0 0 0"/>
    <geometry>
      <mesh filename="package://Xarm6_description/meshes/end_effector_1_1_1.stl" scale="0.001 0.001 0.001"/>
    </geometry>
    <material name="silver"/>
  </visual>
  <collision>
    <origin xyz="-0.207437 0.000906 -0.140853" rpy="0 0 0"/>
    <geometry>
      <mesh filename="package://Xarm6_description/meshes/end_effector_1_1_1.stl" scale="0.001 0.001 0.001"/>
    </geometry>
  </collision>
</link>

<joint name="Revolute 25" type="continuous">
  <origin xyz="3e-06 5e-06 0.1548" rpy="0 0 0"/>
  <parent link="base_link"/>
  <child link="link1_1_1_1"/>
  <axis xyz="1.8e-05 3.2e-05 1.0"/>
</joint>

<joint name="Revolute 26" type="continuous">
  <origin xyz="0.000346 0.075299 0.111998" rpy="0 0 0"/>
  <parent link="link1_1_1_1"/>
  <child link="link2_1_1_1"/>
  <axis xyz="-6.4e-05 1.0 -3.2e-05"/>
</joint>

<joint name="Revolute 27" type="continuous">
  <origin xyz="0.053322 -0.00829 0.284672" rpy="0 0 0"/>
  <parent link="link2_1_1_1"/>
  <child link="link3_1_1_1"/>
  <axis xyz="-6.4e-05 1.0 -3.2e-05"/>
</joint>

<joint name="Revolute 28" type="continuous">
  <origin xyz="0.077754 -0.067496 -0.169105" rpy="0 0 0"/>
  <parent link="link3_1_1_1"/>
  <child link="link4_1_1_1"/>
  <axis xyz="5.6e-05 -3.2e-05 -1.0"/>
</joint>

<joint name="Revolute 29" type="continuous">
  <origin xyz="9e-06 -0.004766 -0.172996" rpy="0 0 0"/>
  <parent link="link4_1_1_1"/>
  <child link="link5_1_1_1"/>
  <axis xyz="-6.4e-05 1.0 -3.2e-05"/>
</joint>

<joint name="Revolute 30" type="continuous">
  <origin xyz="0.076003 0.004342 -0.068516" rpy="0 0 0"/>
  <parent link="link5_1_1_1"/>
  <child link="end_effector_1_1_1"/>
  <axis xyz="5.6e-05 -3.2e-05 -1.0"/>
</joint>

</robot>
